Workbook

Sheet Cpu
A1: Время | B1: CPU | C1: %user | D1: %nice | E1: %system | F1: %iowait | G1: %steal | H1: %idle | I1: Использование CPU | J1: Длина очереди CPU | K1: Сравнение со средним
A2: 0.20018519 | B2: all | C2: 0 | D2: 0 | E2: 0.44 | F2: 0 | G2: 0 | H2: 99.56 | I2: =100-H2 -> 0.44 | J2: =Queue!B2 -> 0 | K2: =IF(C2>AVERAGE($C$2:$C$470),"выше среднего","ниже среднего") -> ниже среднего
A3: 0.20018519 | B3: 0 | C3: 0 | D3: 0 | E3: 0.44 | F3: 0 | G3: 0 | H3: 99.56
A4: 0.20030093 | B4: all | C4: 0 | D4: 0 | E4: 0.22 | F4: 0 | G4: 0 | H4: 99.78 | I4: =100-H4 -> 0.22 | J4: =Queue!B4 -> 0 | K4: =IF(C4>AVERAGE($C$2:$C$470),"выше среднего","ниже среднего") -> ниже среднего
A5: 0.20030093 | B5: 0 | C5: 0 | D5: 0 | E5: 0.22 | F5: 0 | G5: 0 | H5: 99.78
A6: 0.20041667 | B6: all | C6: 0 | D6: 0 | E6: 0.22 | F6: 0.11 | G6: 0 | H6: 99.67 | I6: =100-H6 -> 0.33 | J6: =Queue!B6 -> 0 | K6: =IF(C6>AVERAGE($C$2:$C$470),"выше среднего","ниже среднего") -> ниже среднего
A7: 0.20041667 | B7: 0 | C7: 0 | D7: 0 | E7: 0.22 | F7: 0.11 | G7: 0 | H7: 99.67
A8: 0.20053241 | B8: all | C8: 0 | D8: 0 | E8: 0.22 | F8: 0 | G8: 0 | H8: 99.78 | I8: =100-H8 -> 0.22 | J8: =Queue!B8 -> 0 | K8: =IF(C8>AVERAGE($C$2:$C$470),"выше среднего","ниже среднего") -> ниже среднего
A9: 0.20053241 | B9: 0 | C9: 0 | D9: 0 | E9: 0.22 | F9: 0 | G9: 0 | H9: 99.78
A10: 0.20064815 | B10: all | C10: 0 | D10: 0 | E10: 0.33 | F10: 0 | G10: 0 | H10: 99.67 | I10: =100-H10 -> 0.33 | J10: =Queue!B10 -> 0 | K10: =IF(C10>AVERAGE($C$2:$C$470),"выше среднего","ниже среднего") -> ниже среднего
A11: 0.20064815 | B11: 0 | C11: 0 | D11: 0 | E11: 0.33 | F11: 0 | G11: 0 | H11: 99.67
A12: 0.20076389 | B12: all | C12: 0 | D12: 0 | E12: 0.22 | F12: 0 | G12: 0 | H12: 99.78 | I12: =100-H12 -> 0.22 | J12: =Queue!B12 -> 0 | K12: =IF(C12>AVERAGE($C$2:$C$470),"выше среднего","ниже среднего") -> ниже среднего
A13: 0.20076389 | B13: 0 | C13: 0 | D13: 0 | E13: 0.22 | F13: 0 | G13: 0 | H13: 99.78
A14: 0.20087963 | B14: all | C14: 0 | D14: 0 | E14: 0.33 | F14: 0 | G14: 0 | H14: 99.67 | I14: =100-H14 -> 0.33 | J14: =Queue!B14 -> 0 | K14: =IF(C14>AVERAGE($C$2:$C$470),"выше среднего","ниже среднего") -> ниже среднего
A15: 0.20087963 | B15: 0 | C15: 0 | D15: 0 | E15: 0.33 | F15: 0 | G15: 0 | H15: 99.67
A16: 0.20099537 | B16: all | C16: 0 | D16: 0 | E16: 0.44 | F16: 0 | G16: 0 | H16: 99.56 | I16: =100-H16 -> 0.44 | J16: =Queue!B16 -> 0 | K16: =IF(C16>AVERAGE($C$2:$C$470),"выше среднего","ниже среднего") -> ниже среднего
A17: 0.20099537 | B17: 0 | C17: 0 | D17: 0 | E17: 0.44 | F17: 0 | G17: 0 | H17: 99.56
A18: 0.20111111 | B18: all | C18: 0 | D18: 0 | E18: 0.33 | F18: 0 | G18: 0 | H18: 99.67 | I18: =100-H18 -> 0.33 | J18: =Queue!B18 -> 0 | K18: =IF(C18>AVERAGE($C$2:$C$470),"выше среднего","ниже среднего") -> ниже среднего
A19: 0.20111111 | B19: 0 | C19: 0 | D19: 0 | E19: 0.33 | F19: 0 | G19: 0 | H19: 99.67
A20: 0.20122685 | B20: all | C20: 0 | D20: 0 | E20: 0.22 | F20: 0.11 | G20: 0 | H20: 99.67 | I20: =100-H20 -> 0.33 | J20: =Queue!B20 -> 0 | K20: =IF(C20>AVERAGE($C$2:$C$470),"выше среднего","ниже среднего") -> ниже среднего
A21: 0.20122685 | B21: 0 | C21: 0 | D21: 0 | E21: 0.22 | F21: 0.11 | G21: 0 | H21: 99.67
A22: 0.20134259 | B22: all | C22: 0 | D22: 0 | E22: 0.22 | F22: 0 | G22: 0 | H22: 99.78 | I22: =100-H22 -> 0.22 | J22: =Queue!B22 -> 0 | K22: =IF(C22>AVERAGE($C$2:$C$470),"выше среднего","ниже среднего") -> ниже среднего
A23: 0.20134259 | B23: 0 | C23: 0 | D23: 0 | E23: 0.22 | F23: 0 | G23: 0 | H23: 99.78
A24: 0.20145833 | B24: all | C24: 0.11 | D24: 0 | E24: 0.33 | F24: 0 | G24: 0 | H24: 99.56 | I24: =100-H24 -> 0.44 | J24: =Queue!B24 -> 0 | K24: =IF(C24>AVERAGE($C$2:$C$470),"выше среднего","ниже среднего") -> выше среднего
A25: 0.20145833 | B25: 0 | C25: 0.11 | D25: 0 | E25: 0.33 | F25: 0 | G25: 0 | H25: 99.56
A26: 0.20157407 | B26: all | C26: 0 | D26: 0 | E26: 0.44 | F26: 0 | G26: 0 | H26: 99.56 | I26: =100-H26 -> 0.44 | J26: =Queue!B26 -> 0 | K26: =IF(C26>AVERAGE($C$2:$C$470),"выше среднего","ниже среднего") -> ниже среднего
A27: 0.20157407 | B27: 0 | C27: 0 | D27: 0 | E27: 0.44 | F27: 0 | G27: 0 | H27: 99.56
A28: 0.20168981 | B28: all | C28: 0 | D28: 0 | E28: 0.11 | F28: 0 | G28: 0 | H28: 99.89 | I28: =100-H28 -> 0.11 | J28: =Queue!B28 -> 0 | K28: =IF(C28>AVERAGE($C$2:$C$470),"выше среднего","ниже среднего") -> ниже среднего
A29: 0.20168981 | B29: 0 | C29: 0 | D29: 0 | E29: 0.11 | F29: 0 | G29: 0 | H29: 99.89
A30: 0.20180556 | B30: all | C30: 0 | D30: 0 | E30: 0.33 | F30: 0.11 | G30: 0 | H30: 99.56 | I30: =100-H30 -> 0.44 | J30: =Queue!B30 -> 0 | K30: =IF(C30>AVERAGE($C$2:$C$470),"выше среднего","ниже среднего") -> ниже среднего
A31: 0.20180556 | B31: 0 | C31: 0 | D31: 0 | E31: 0.33 | F31: 0.11 | G31: 0 | H31: 99.56
A32: 0.2019213 | B32: all | C32: 0 | D32: 0 | E32: 0.33 | F32: 0 | G32: 0 | H32: 99.67 | I32: =100-H32 -> 0.33 | J32: =Queue!B32 -> 0 | K32: =IF(C32>AVERAGE($C$2:$C$470),"выше среднего","ниже среднего") -> ниже среднего
A33: 0.2019213 | B33: 0 | C33: 0 | D33: 0 | E33: 0.33 | F33: 0 | G33: 0 | H33: 99.67
A34: 0.20203704 | B34: all | C34: 0 | D34: 0 | E34: 0.33 | F34: 0 | G34: 0 | H34: 99.67 | I34: =100-H34 -> 0.33 | J34: =Queue!B34 -> 0 | K34: =IF(C34>AVERAGE($C$2:$C$470),"выше среднего","ниже среднего") -> ниже среднего
A35: 0.20203704 | B35: 0 | C35: 0 | D35: 0 | E35: 0.33 | F35: 0 | G35: 0 | H35: 99.67
A36: 0.20215278 | B36: all | C36: 0 | D36: 0 | E36: 0.22 | F36: 0 | G36: 0 | H36: 99.78 | I36: =100-H36 -> 0.22 | J36: =Queue!B36 -> 0 | K36: =IF(C36>AVERAGE($C$2:$C$470),"выше среднего","ниже среднего") -> ниже среднего
A37: 0.20215278 | B37: 0 | C37: 0 | D37: 0 | E37: 0.22 | F37: 0 | G37: 0 | H37: 99.78
A38: 0.20226852 | B38: all | C38: 0 | D38: 0 | E38: 0.33 | F38: 0 | G38: 0 | H38: 99.67 | I38: =100-H38 -> 0.33 | J38: =Queue!B38 -> 0 | K38: =IF(C38>AVERAGE($C$2:$C$470),"выше среднего","ниже среднего") -> ниже среднего
A39: 0.20226852 | B39: 0 | C39: 0 | D39: 0 | E39: 0.33 | F39: 0 | G39: 0 | H39: 99.67
A40: 0.20238426 | B40: all | C40: 0 | D40: 0 | E40: 0.11 | F40: 0 | G40: 0 | H40: 99.89 | I40: =100-H40 -> 0.11 | J40: =Queue!B40 -> 0 | K40: =IF(C40>AVERAGE($C$2:$C$470),"выше среднего","ниже среднего") -> ниже среднего
...

Sheet Queue
A1: Время | B1: runq-sz | C1: plist-sz | D1: ldavg-1 | E1: ldavg-5 | F1: ldavg-15 | G1: blocked
A2: 0.20018519 | B2: 0 | C2: 121 | D2: 0.00 | E2: 0.00 | F2: 0.01 | G2: 0
A3: 0.20030093 | B3: 0 | C3: 122 | D3: 0.00 | E3: 0.00 | F3: 0.00 | G3: 0
A4: 0.20041667 | B4: 0 | C4: 122 | D4: 0.00 | E4: 0.00 | F4: 0.00 | G4: 0
A5: 0.20053241 | B5: 0 | C5: 122 | D5: 0.00 | E5: 0.00 | F5: 0.00 | G5: 0
A6: 0.20064815 | B6: 0 | C6: 122 | D6: 0.00 | E6: 0.00 | F6: 0.00 | G6: 0
A7: 0.20076389 | B7: 0 | C7: 122 | D7: 0.00 | E7: 0.00 | F7: 0.00 | G7: 0
A8: 0.20087963 | B8: 0 | C8: 122 | D8: 0.00 | E8: 0.00 | F8: 0.00 | G8: 0
A9: 0.20099537 | B9: 0 | C9: 122 | D9: 0.00 | E9: 0.00 | F9: 0.00 | G9: 0
A10: 0.20111111 | B10: 0 | C10: 122 | D10: 0.00 | E10: 0.00 | F10: 0.00 | G10: 0
A11: 0.20122685 | B11: 0 | C11: 122 | D11: 0.00 | E11: 0.00 | F11: 0.00 | G11: 0
A12: 0.20134259 | B12: 0 | C12: 122 | D12: 0.00 | E12: 0.00 | F12: 0.00 | G12: 0
A13: 0.20145833 | B13: 0 | C13: 124 | D13: 0.00 | E13: 0.00 | F13: 0.00 | G13: 0
... A241: 0.22784722 | B241: 0 | C241: 125 | D241: 0.00 | E241: 0.00 | F241: 0.00 | G241: 0
A242: Average: | B242: 0 | C242: 127 | D242: 0.00 | E242: 0.00 | F242: 0.00 | G242: 0

Sheet Memory
A1: Время | B1: kbmemfree | C1: kbavail | D1: kbmemused | E1: %memused | F1: kbbuffers | G1: kbcached | H1: kbcommit | I1: %commit | J1: kbactive | K1: kbinact | L1: kbdirty | M1: kbanonpg | N1: kbslab | O1: kbkstack | P1: kbpgtbl | Q1: kbvmused | R1: %swpused число
A2: 0.20018519 | B2: 1579632 | C2: 1704472 | D2: 120736 | E2: 5.99 | F2: 19368 | G2: 238416 | H2: 248996 | I2: 12.36 | J2: 237864 | K2: 53968 | L2: 44 | M2: 61372 | N2: 57144 | O2: 1936 | P2: 2536 | Q2: 21988 | R2: =Swap!D2 -> 0
A3: 0.20030093 | B3: 1579632 | C3: 1704484 | D3: 120700 | E3: 5.99 | F3: 19376 | G3: 238420 | H3: 248996 | I3: 12.36 | J3: 237892 | K3: 53980 | L3: 44 | M3: 61400 | N3: 57168 | O3: 1952 | P3: 2536 | Q3: 22004 | R3: =Swap!D3 -> 0
A4: 0.20041667 | B4: 1579632 | C4: 1704504 | D4: 120688 | E4: 5.99 | F4: 19384 | G4: 238424 | H4: 248996 | I4: 12.36 | J4: 237892 | K4: 54000 | L4: 8 | M4: 61400 | N4: 57168 | O4: 1952 | P4: 2536 | Q4: 22004 | R4: =Swap!D4 -> 0
A5: 0.20053241 | B5: 1579632 | C5: 1704504 | D5: 120676 | E5: 5.99 | F5: 19392 | G5: 238428 | H5: 248996 | I5: 12.36 | J5: 237892 | K5: 54000 | L5: 16 | M5: 61400 | N5: 57168 | O5: 1952 | P5: 2536 | Q5: 22004 | R5: =Swap!D5 -> 0
A6: 0.20064815 | B6: 1579632 | C6: 1704504 | D6: 120668 | E6: 5.99 | F6: 19400 | G6: 238428 | H6: 248996 | I6: 12.36 | J6: 237892 | K6: 54000 | L6: 16 | M6: 61400 | N6: 57168 | O6: 1952 | P6: 2536 | Q6: 22004 | R6: =Swap!D6 -> 0
A7: 0.20076389 | B7: 1579632 | C7: 1704528 | D7: 120656 | E7: 5.99 | F7: 19408 | G7: 238432 | H7: 248996 | I7: 12.36 | J7: 237892 | K7: 54024 | L7: 12 | M7: 61400 | N7: 57168 | O7: 1952 | P7: 2536 | Q7: 22004 | R7: =Swap!D7 -> 0
A8: 0.20087963 | B8: 1579632 | C8: 1704548 | D8: 120644 | E8: 5.99 | F8: 19416 | G8: 238436 | H8: 248996 | I8: 12.36 | J8: 237892 | K8: 54044 | L8: 8 | M8: 61400 | N8: 57168 | O8: 1952 | P8: 2536 | Q8: 22004 | R8: =Swap!D8 -> 0
A9: 0.20099537 | B9: 1579632 | C9: 1704548 | D9: 120632 | E9: 5.99 | F9: 19424 | G9: 238440 | H9: 248996 | I9: 12.36 | J9: 237892 | K9: 54044 | L9: 20 | M9: 61400 | N9: 57168 | O9: 1952 | P9: 2536 | Q9: 22004 | R9: =Swap!D9 -> 0
A10: 0.20111111 | B10: 1579632 | C10: 1704548 | D10: 120620 | E10: 5.99 | F10: 19432 | G10: 238444 | H10: 248996 | I10: 12.36 | J10: 237892 | K10: 54044 | L10: 24 | M10: 61400 | N10: 57168 | O10: 1952 | P10: 2536 | Q10: 22004 | R10: =Swap!D10 -> 0
A11: 0.20122685 | B11: 1579632 | C11: 1704580 | D11: 120604 | E11: 5.98 | F11: 19440 | G11: 238448 | H11: 248996 | I11: 12.36 | J11: 237892 | K11: 54072 | L11: 16 | M11: 61400 | N11: 57172 | O11: 1952 | P11: 2536 | Q11: 22004 | R11: =Swap!D11 -> 0
A12: 0.20134259 | B12: 1579632 | C12: 1704592 | D12: 120592 | E12: 5.98 | F12: 19448 | G12: 238452 | H12: 248996 | I12: 12.36 | J12: 237892 | K12: 54084 | L12: 12 | M12: 61400 | N12: 57172 | O12: 1952 | P12: 2536 | Q12: 22004 | R12: =Swap!D12 -> 0
A13: 0.20145833 | B13: 1579380 | C13: 1704372 | D13: 120812 | E13: 5.99 | F13: 19464 | G13: 238460 | H13: 248996 | I13: 12.36 | J13: 237892 | K13: 54116 | L13: 188 | M13: 61400 | N13: 57180 | O13: 1984 | P13: 2536 | Q13: 22052 | R13: =Swap!D13 -> 0
... A241: 0.22784722 | B241: 1508652 | C241: 1673824 | D241: 150204 | E241: 7.45 | F241: 22192 | G241: 275276 | H241: 284028 | I241: 14.09 | J241: 257592 | K241: 75708 | L241: 4 | M241: 63148 | N241: 58972 | O241: 2000 | P241: 2652 | Q241: 22144 | R241: =Swap!D241 -> 0
A242: Average: | B242: 1518082 | C242: 1675673 | D242: 148507 | E242: 7.37 | F242: 20925 | G242: 269093 | H242: 312000 | I242: 15.48 | J242: 256565 | K242: 71198 | L242: 38 | M242: 65073 | N242: 58690 | O242: 2036 | P242: 2736 | Q242: 22190 | R242: =Swap!D242 -> 0

Sheet Swap
A1: Время | B1: kbswpfree | C1: kbswpused | D1: %swpused | E1: kbswpcad | F1: %swpcad
A2: 0.20018519 | B2: 0 | C2: 0 | D2: 0 | E2: 0 | F2: 0
A3: 0.20030093 | B3: 0 | C3: 0 | D3: 0 | E3: 0 | F3: 0
A4: 0.20041667 | B4: 0 | C4: 0 | D4: 0 | E4: 0 | F4: 0
A5: 0.20053241 | B5: 0 | C5: 0 | D5: 0 | E5: 0 | F5: 0
A6: 0.20064815 | B6: 0 | C6: 0 | D6: 0 | E6: 0 | F6: 0
A7: 0.20076389 | B7: 0 | C7: 0 | D7: 0 | E7: 0 | F7: 0
A8: 0.20087963 | B8: 0 | C8: 0 | D8: 0 | E8: 0 | F8: 0
A9: 0.20099537 | B9: 0 | C9: 0 | D9: 0 | E9: 0 | F9: 0
A10: 0.20111111 | B10: 0 | C10: 0 | D10: 0 | E10: 0 | F10: 0
A11: 0.20122685 | B11: 0 | C11: 0 | D11: 0 | E11: 0 | F11: 0
A12: 0.20134259 | B12: 0 | C12: 0 | D12: 0 | E12: 0 | F12: 0
A13: 0.20145833 | B13: 0 | C13: 0 | D13: 0 | E13: 0 | F13: 0
... A241: 0.22784722 | B241: 0 | C241: 0 | D241: 0 | E241: 0 | F241: 0
A242: Average: | B242: 0 | C242: 0 | D242: 0 | E242: 0 | F242: 0

Sheet Network
A1: Время | B1: IFACE | C1: rxpck/s | D1: txpck/s | E1: rxkB/s | F1: txkB/s | G1: rxcmp/s | H1: txcmp/s | I1: rxmcst/s | J1: %ifutil | K1: Получаемые данные, Кбит/с | L1: Передаваемые данные, Кбит/с
A2: 0.20018519 | B2: lo | C2: 0 | D2: 0 | E2: 0 | F2: 0 | G2: 0 | H2: 0 | I2: 0 | J2: 0 | K2: =IF(B2="enp0s3",E2*8,NA()) -> #N/A | L2: =IF(B2="enp0s3",F2*8,NA()) -> #N/A
A3: 0.20018519 | B3: enp0s3 | C3: 1.2 | D3: 0.1 | E3: 0.1 | F3: 0.02 | G3: 0 | H3: 0 | I3: 0 | J3: 0 | K3: =IF(B3="enp0s3",E3*8,NA()) -> 0.8 | L3: =IF(B3="enp0s3",F3*8,NA()) -> 0.16
A4: 0.20030093 | B4: lo | C4: 0 | D4: 0 | E4: 0 | F4: 0 | G4: 0 | H4: 0 | I4: 0 | J4: 0 | K4: =IF(B4="enp0s3",E4*8,NA()) -> #N/A | L4: =IF(B4="enp0s3",F4*8,NA()) -> #N/A
A5: 0.20030093 | B5: enp0s3 | C5: 0.9 | D5: 1.3 | E5: 0.09 | F5: 1.48 | G5: 0 | H5: 0 | I5: 0 | J5: 0 | K5: =IF(B5="enp0s3",E5*8,NA()) -> 0.72 | L5: =IF(B5="enp0s3",F5*8,NA()) -> 11.84
A6: 0.20041667 | B6: lo | C6: 0 | D6: 0 | E6: 0 | F6: 0 | G6: 0 | H6: 0 | I6: 0 | J6: 0 | K6: =IF(B6="enp0s3",E6*8,NA()) -> #N/A | L6: =IF(B6="enp0s3",F6*8,NA()) -> #N/A
A7: 0.20041667 | B7: enp0s3 | C7: 1 | D7: 1.1 | E7: 0.06 | F7: 1.46 | G7: 0 | H7: 0 | I7: 0 | J7: 0 | K7: =IF(B7="enp0s3",E7*8,NA()) -> 0.48 | L7: =IF(B7="enp0s3",F7*8,NA()) -> 11.68
A8: 0.20053241 | B8: lo | C8: 0 | D8: 0 | E8: 0 | F8: 0 | G8: 0 | H8: 0 | I8: 0 | J8: 0 | K8: =IF(B8="enp0s3",E8*8,NA()) -> #N/A | L8: =IF(B8="enp0s3",F8*8,NA()) -> #N/A
A9: 0.20053241 | B9: enp0s3 | C9: 1.3 | D9: 1.2 | E9: 0.13 | F9: 1.47 | G9: 0 | H9: 0 | I9: 0 | J9: 0 | K9: =IF(B9="enp0s3",E9*8,NA()) -> 1.04 | L9: =IF(B9="enp0s3",F9*8,NA()) -> 11.76
A10: 0.20064815 | B10: lo | C10: 0 | D10: 0 | E10: 0 | F10: 0 | G10: 0 | H10: 0 | I10: 0 | J10: 0 | K10: =IF(B10="enp0s3",E10*8,NA()) -> #N/A | L10: =IF(B10="enp0s3",F10*8,NA()) -> #N/A
A11: 0.20064815 | B11: enp0s3 | C11: 1.2 | D11: 1.3 | E11: 0.09 | F11: 1.47 | G11: 0 | H11: 0 | I11: 0 | J11: 0 | K11: =IF(B11="enp0s3",E11*8,NA()) -> 0.72 | L11: =IF(B11="enp0s3",F11*8,NA()) -> 11.76
A12: 0.20076389 | B12: lo | C12: 0 | D12: 0 | E12: 0 | F12: 0 | G12: 0 | H12: 0 | I12: 0 | J12: 0 | K12: =IF(B12="enp0s3",E12*8,NA()) -> #N/A | L12: =IF(B12="enp0s3",F12*8,NA()) -> #N/A
A13: 0.20076389 | B13: enp0s3 | C13: 0.9 | D13: 1.2 | E13: 0.07 | F13: 1.47 | G13: 0 | H13: 0 | I13: 0.1 | J13: 0 | K13: =IF(B13="enp0s3",E13*8,NA()) -> 0.56 | L13: =IF(B13="enp0s3",F13*8,NA()) -> 11.76
... A15: 0.20087963 | B15: enp0s3 | C15: 1.6 | D15: 1.1 | E15: 0.13 | F15: 1.46 | G15: 0 | H15: 0 | I15: 0 | J15: 0 | K15: =IF(B15="enp0s3",E15*8,NA()) -> 1.04 | L15: =IF(B15="enp0s3",F15*8,NA()) -> 11.68
A16: 0.20099537 | B16: lo | C16: 0 | D16: 0 | E16: 0 | F16: 0 | G16: 0 | H16: 0 | I16: 0 | J16: 0
A17: 0.20099537 | B17: enp0s3 | C17: 1.6 | D17: 1.3 | E17: 0.11 | F17: 1.47 | G17: 0 | H17: 0 | I17: 0 | J17: 0 | K17: =IF(B17="enp0s3",E17*8,NA()) -> 0.88 | L17: =IF(B17="enp0s3",F17*8,NA()) -> 11.76
A18: 0.20111111 | B18: lo | C18: 0 | D18: 0 | E18: 0 | F18: 0 | G18: 0 | H18: 0 | I18: 0 | J18: 0
A19: 0.20111111 | B19: enp0s3 | C19: 1.1 | D19: 1.3 | E19: 0.08 | F19: 1.47 | G19: 0 | H19: 0 | I19: 0 | J19: 0 | K19: =IF(B19="enp0s3",E19*8,NA()) -> 0.64 | L19: =IF(B19="enp0s3",F19*8,NA()) -> 11.76
A20: 0.20122685 | B20: lo | C20: 0 | D20: 0 | E20: 0 | F20: 0 | G20: 0 | H20: 0 | I20: 0 | J20: 0
A21: 0.20122685 | B21: enp0s3 | C21: 0.8 | D21: 1.2 | E21: 0.1 | F21: 1.47 | G21: 0 | H21: 0 | I21: 0 | J21: 0 | K21: =IF(B21="enp0s3",E21*8,NA()) -> 0.8 | L21: =IF(B21="enp0s3",F21*8,NA()) -> 11.76
A22: 0.20134259 | B22: lo | C22: 0 | D22: 0 | E22: 0 | F22: 0 | G22: 0 | H22: 0 | I22: 0 | J22: 0
A23: 0.20134259 | B23: enp0s3 | C23: 1.1 | D23: 1.1 | E23: 0.07 | F23: 1.46 | G23: 0 | H23: 0 | I23: 0 | J23: 0 | K23: =IF(B23="enp0s3",E23*8,NA()) -> 0.56 | L23: =IF(B23="enp0s3",F23*8,NA()) -> 11.68
A24: 0.20145833 | B24: lo | C24: 0 | D24: 0 | E24: 0 | F24: 0 | G24: 0 | H24: 0 | I24: 0 | J24: 0
A25: 0.20145833 | B25: enp0s3 | C25: 2.1 | D25: 1.2 | E25: 0.14 | F25: 1.47 | G25: 0 | H25: 0 | I25: 0 | J25: 0 | K25: =IF(B25="enp0s3",E25*8,NA()) -> 1.12 | L25: =IF(B25="enp0s3",F25*8,NA()) -> 11.76
A26: 0.20157407 | B26: lo | C26: 0 | D26: 0 | E26: 0 | F26: 0 | G26: 0 | H26: 0 | I26: 0 | J26: 0
A27: 0.20157407 | B27: enp0s3 | C27: 1.4 | D27: 1.3 | E27: 0.13 | F27: 1.47 | G27: 0 | H27: 0 | I27: 0 | J27: 0 | K27: =IF(B27="enp0s3",E27*8,NA()) -> 1.04 | L27: =IF(B27="enp0s3",F27*8,NA()) -> 11.76
A28: 0.20168981 | B28: lo | C28: 0 | D28: 0 | E28: 0 | F28: 0 | G28: 0 | H28: 0 | I28: 0 | J28: 0
A29: 0.20168981 | B29: enp0s3 | C29: 0.8 | D29: 1.2 | E29: 0.07 | F29: 1.47 | G29: 0 | H29: 0 | I29: 0 | J29: 0 | K29: =IF(B29="enp0s3",E29*8,NA()) -> 0.56 | L29: =IF(B29="enp0s3",F29*8,NA()) -> 11.76
A30: 0.20180556 | B30: lo | C30: 0 | D30: 0 | E30: 0 | F30: 0 | G30: 0 | H30: 0 | I30: 0 | J30: 0
A31: 0.20180556 | B31: enp0s3 | C31: 0.6 | D31: 1.1 | E31: 0.04 | F31: 1.46 | G31: 0 | H31: 0 | I31: 0 | J31: 0 | K31: =IF(B31="enp0s3",E31*8,NA()) -> 0.32 | L31: =IF(B31="enp0s3",F31*8,NA()) -> 11.68
A32: 0.2019213 | B32: lo | C32: 0 | D32: 0 | E32: 0 | F32: 0 | G32: 0 | H32: 0 | I32: 0 | J32: 0
A33: 0.2019213 | B33: enp0s3 | C33: 1 | D33: 1.2 | E33: 0.11 | F33: 1.47 | G33: 0 | H33: 0 | I33: 0 | J33: 0 | K33: =IF(B33="enp0s3",E33*8,NA()) -> 0.88 | L33: =IF(B33="enp0s3",F33*8,NA()) -> 11.76
A34: 0.20203704 | B34: lo | C34: 0 | D34: 0 | E34: 0 | F34: 0 | G34: 0 | H34: 0 | I34: 0 | J34: 0
A35: 0.20203704 | B35: enp0s3 | C35: 0.9 | D35: 1.3 | E35: 0.07 | F35: 1.48 | G35: 0 | H35: 0 | I35: 0 | J35: 0 | K35: =IF(B35="enp0s3",E35*8,NA()) -> 0.56 | L35: =IF(B35="enp0s3",F35*8,NA()) -> 11.84
A36: 0.20215278 | B36: lo | C36: 0 | D36: 0 | E36: 0 | F36: 0 | G36: 0 | H36: 0 | I36: 0 | J36: 0
A37: 0.20215278 | B37: enp0s3 | C37: 1.2 | D37: 1.3 | E37: 0.09 | F37: 1.47 | G37: 0 | H37: 0 | I37: 0 | J37: 0 | K37: =IF(B37="enp0s3",E37*8,NA()) -> 0.72 | L37: =IF(B37="enp0s3",F37*8,NA()) -> 11.76
A38: 0.20226852 | B38: lo | C38: 0 | D38: 0 | E38: 0 | F38: 0 | G38: 0 | H38: 0 | I38: 0 | J38: 0
A39: 0.20226852 | B39: enp0s3 | C39: 0.9 | D39: 1.3 | E39: 0.09 | F39: 1.48 | G39: 0 | H39: 0 | I39: 0.1 | J39: 0 | K39: =IF(B39="enp0s3",E39*8,NA()) -> 0.72 | L39: =IF(B39="enp0s3",F39*8,NA()) -> 11.84
A40: 0.20238426 | B40: lo | C40: 0 | D40: 0 | E40: 0 | F40: 0 | G40: 0 | H40: 0 | I40: 0 | J40: 0
A41: 0.20238426 | B41: enp0s3 | C41: 0.9 | D41: 1.2 | E41: 0.07 | F41: 1.47 | G41: 0 | H41: 0 | I41: 0 | J41: 0 | K41: =IF(B41="enp0s3",E41*8,NA()) -> 0.56 | L41: =IF(B41="enp0s3",F41*8,NA()) -> 11.76
...

Sheet Disk
A1: Время | B1: tps | C1: rkB/s | D1: wkB/s | E1: dkB/s | F1: areq-sz | G1: aqu-sz | H1: await | I1: %util | J1: DEV | K1: Среднее время выполнения чтения/записи sda | L1: Среднее время обслуживания чтения/записи | M1: Среднее время выполнения чтения/записи sda2
A2: 0.20018519 | B2: 0 | C2: 0 | D2: 0 | E2: 0 | F2: 0 | G2: 0 | H2: 0 | I2: 0 | J2: loop0 | K2: =IF(J2="sda",H2,NA()) -> #N/A | L2: =NA() -> #N/A | M2: =IF(J2="sda2",H2,NA()) -> #N/A
A3: 0.20018519 | B3: 0.3 | C3: 0 | D3: 6 | E3: 0 | F3: 20 | G3: 0 | H3: 0.67 | I3: 0.02 | J3: sda | K3: =IF(J3="sda",H3,NA()) -> 0.67 | L3: =NA() -> #N/A | M3: =IF(J3="sda2",H3,NA()) -> #N/A
A4: 0.20018519 | B4: 0 | C4: 0 | D4: 0 | E4: 0 | F4: 0 | G4: 0 | H4: 0 | I4: 0 | J4: sda1 | K4: =IF(J4="sda",H4,NA()) -> #N/A | L4: =NA() -> #N/A | M4: =IF(J4="sda2",H4,NA()) -> #N/A
A5: 0.20018519 | B5: 0.3 | C5: 0 | D5: 6 | E5: 0 | F5: 20 | G5: 0 | H5: 0.67 | I5: 0.02 | J5: sda2 | K5: =IF(J5="sda",H5,NA()) -> #N/A | L5: =NA() -> #N/A | M5: =IF(J5="sda2",H5,NA()) -> 0.67
A6: 0.20030093 | B6: 0 | C6: 0 | D6: 0 | E6: 0 | F6: 0 | G6: 0 | H6: 0 | I6: 0 | J6: loop0 | K6: =IF(J6="sda",H6,NA()) -> #N/A | L6: =NA() -> #N/A | M6: =IF(J6="sda2",H6,NA()) -> #N/A
A7: 0.20030093 | B7: 0.3 | C7: 0 | D7: 2.8 | E7: 0 | F7: 9.33 | G7: 0 | H7: 1 | I7: 0.02 | J7: sda | K7: =IF(J7="sda",H7,NA()) -> 1 | L7: =NA() -> #N/A | M7: =IF(J7="sda2",H7,NA()) -> #N/A
A8: 0.20030093 | B8: 0 | C8: 0 | D8: 0 | E8: 0 | F8: 0 | G8: 0 | H8: 0 | I8: 0 | J8: sda1 | K8: =IF(J8="sda",H8,NA()) -> #N/A | L8: =NA() -> #N/A | M8: =IF(J8="sda2",H8,NA()) -> #N/A
A9: 0.20030093 | B9: 0.3 | C9: 0 | D9: 2.8 | E9: 0 | F9: 9.33 | G9: 0 | H9: 1 | I9: 0.02 | J9: sda2 | K9: =IF(J9="sda",H9,NA()) -> #N/A | L9: =NA() -> #N/A | M9: =IF(J9="sda2",H9,NA()) -> 1
A10: 0.20041667 | B10: 0 | C10: 0 | D10: 0 | E10: 0 | F10: 0 | G10: 0 | H10: 0 | I10: 0 | J10: loop0 | K10: =IF(J10="sda",H10,NA()) -> #N/A | L10: =NA() -> #N/A | M10: =IF(J10="sda2",H10,NA()) -> #N/A
A11: 0.20041667 | B11: 1.1 | C11: 0 | D11: 5.6 | E11: 0 | F11: 5.09 | G11: 0 | H11: 0.64 | I11: 0.01 | J11: sda | K11: =IF(J11="sda",H11,NA()) -> 0.64 | L11: =NA() -> #N/A | M11: =IF(J11="sda2",H11,NA()) -> #N/A
A12: 0.20041667 | B12: 0 | C12: 0 | D12: 0 | E12: 0 | F12: 0 | G12: 0 | H12: 0 | I12: 0 | J12: sda1 | K12: =IF(J12="sda",H12,NA()) -> #N/A | L12: =NA() -> #N/A | M12: =IF(J12="sda2",H12,NA()) -> #N/A
A13: 0.20041667 | B13: 1.1 | C13: 0 | D13: 5.6 | E13: 0 | F13: 5.09 | G13: 0 | H13: 0.64 | I13: 0.01 | J13: sda2 | K13: =IF(J13="sda",H13,NA()) -> #N/A | L13: =NA() -> #N/A | M13: =IF(J13="sda2",H13,NA()) -> 0.64
... A961: 0.22784722 | B961: 0.3 | C961: 0 | D961: 2.8 | E961: 0 | F961: 9.33 | G961: 0 | H961: 1 | I961: 0.03 | J961: sda2 | K961: =IF(J961="sda",H961,NA()) -> #N/A | L961: =NA() -> #N/A | M961: =IF(J961="sda2",H961,NA()) -> 1
A962: Average: | B962: 0 | C962: 0 | D962: 0 | E962: 0 | F962: 0 | G962: 0 | H962: 0 | I962: 0 | J962: loop0
A963: Average: | B963: 0.84 | C963: 15.08 | D963: 11.84 | E963: 0 | F963: 32.13 | G963: 0 | H963: 1.01 | I963: 0.05 | J963: sda
A964: Average: | B964: 0 | C964: 0 | D964: 0 | E964: 0 | F964: 0 | G964: 0 | H964: 0 | I964: 0 | J964: sda1
A965: Average: | B965: 0.84 | C965: 15.08 | D965: 11.84 | E965: 0 | F965: 32.13 | G965: 0 | H965: 1.01 | I965: 0.05 | J965: sda2

Sheet сводная таблица1
A3: Названия строк | B3: Среднее по полю Использование памяти | C3: Среднее по полю Использование подкачки | D3: Сумма по полю Использование CPU | E3: Сумма по полю Среднее время выполнения чтения/записи sda | F3: Среднее по полю Длина очереди CPU | G3: Среднее по полю Среднее время обслуживания чтения/записи | H3: Среднее по полю Получаемые данные enp0s3, Кбит/с | I3: Среднее по полю Передаваемые данные enp0s3, Кбит/с
A4: 0.20018519 | B4: 5.99 | C4: 0 | D4: 0.44 | E4: 0.67 | F4: 0 | G4: 0.67 | H4: 0.8 | I4: 0.16
A5: 0.20030093 | B5: 5.99 | C5: 0 | D5: 0.22 | E5: 1 | F5: 0 | G5: 1 | H5: 0.72 | I5: 11.84
A6: 0.20041667 | B6: 5.99 | C6: 0 | D6: 0.33 | E6: 0.64 | F6: 0 | G6: 0.64 | H6: 0.48 | I6: 11.68
A7: 0.20053241 | B7: 5.99 | C7: 0 | D7: 0.22 | E7: 1 | F7: 0 | G7: 1 | H7: 1.04 | I7: 11.76
A8: 0.20064815 | B8: 5.99 | C8: 0 | D8: 0.33 | E8: 1 | F8: 0 | G8: 1 | H8: 0.72 | I8: 11.76
A9: 0.20076389 | B9: 5.99 | C9: 0 | D9: 0.22 | E9: 0.67 | F9: 0 | G9: 0.67 | H9: 0.56 | I9: 11.76
A10: 0.20087963 | B10: 5.99 | C10: 0 | D10: 0.33 | E10: 1 | F10: 0 | G10: 1 | H10: 1.04 | I10: 11.68
A11: 0.20099537 | B11: 5.99 | C11: 0 | D11: 0.44 | E11: 1 | F11: 0 | G11: 1 | H11: 0.88 | I11: 11.76
A12: 0.20111111 | B12: 5.99 | C12: 0 | D12: 0.33 | E12: 1.5 | F12: 0 | G12: 1.5 | H12: 0.64 | I12: 11.76
A13: 0.20122685 | B13: 5.98 | C13: 0 | D13: 0.33 | E13: 1 | F13: 0 | G13: 1 | H13: 0.8 | I13: 11.76
A14: 0.20134259 | B14: 5.98 | C14: 0 | D14: 0.22 | E14: 1.2 | F14: 0 | G14: 1.2 | H14: 0.56 | I14: 11.68
A15: 0.20145833 | B15: 5.99 | C15: 0 | D15: 0.44 | E15: 0.8 | F15: 0 | G15: 0.8 | H15: 1.12 | I15: 11.76
... A243: 0.22784722 | B243: 7.45 | C243: 0 | D243: 0.44 | E243: 1 | F243: 0 | G243: 1 | H243: 0.56 | I243: 11.76
A244: Общий итог | B244: 7.369 | C244: 0 | D244: 107.49 | E244: 269.76 | F244: 0 | G244: 1.1241667 | H244: 9.5016667 | I244: 11.770667

Sheet сводная таблица2
A1: Время | B1: Использование памяти | C1: Использование подкачки | D1: Использование CPU | E1: Длина очереди CPU | F1: Среднее время выполнения чтения/записи sda | G1: Среднее время обслуживания чтения/записи | H1: Получаемые данные enp0s3, Кбит/с | I1: Передаваемые данные enp0s3, Кбит/с
A2: =Memory!A2 -> 0.20018519 | B2: =Memory!E2 -> 5.99 | C2: =Swap!D2 -> 0 | D2: =IFERROR(INDEX(Cpu!$I$2:$I$480,MATCH(A2,Cpu!$A$2:$A$480,0)),"не найдено") -> 0.44 | E2: =IFERROR(INDEX(Cpu!$J$2:$J$480,MATCH(A2,Cpu!$A$2:$A$480,0)),"не найдено") -> 0 | F2: =IFERROR(SUMIFS(Disk!$H$2:$H$961,Disk!$A$2:$A$961,A2,Disk!$J$2:$J$961,"sda"),"не найдено") -> 0.67 | G2: =IF(COUNTIFS(Disk!$A$2:$A$961,A2,Disk!$J$2:$J$961,"sda2")=0,"не найдено",SUMIFS(Disk!$H$2:$H$961,Disk!$A$2:$A$961,A2,Disk!$J$2:$J$961,"sda2")) -> 0.67 | H2: =IF(COUNTIFS(Network!$A$2:$A$481,A2,Network!$B$2:$B$481,"enp0s3")=0,"не найдено",SUMIFS(Network!$K$2:$K$481,Network!$A$2:$A$481,A2,Network!$B$2:$B$481,"enp0s3")) -> 0.8 | I2: =IF(COUNTIFS(Network!$A$2:$A$481,A2,Network!$B$2:$B$481,"enp0s3")=0,"не найдено",SUMIFS(Network!$L$2:$L$481,Network!$A$2:$A$481,A2,Network!$B$2:$B$481,"enp0s3")) -> 0.16
A3: =Memory!A3 -> 0.20030093 | B3: =Memory!E3 -> 5.99 | C3: =Swap!D3 -> 0 | D3: =IFERROR(INDEX(Cpu!$I$2:$I$480,MATCH(A3,Cpu!$A$2:$A$480,0)),"не найдено") -> 0.22 | E3: =IFERROR(INDEX(Cpu!$J$2:$J$480,MATCH(A3,Cpu!$A$2:$A$480,0)),"не найдено") -> 0 | F3: =IFERROR(SUMIFS(Disk!$H$2:$H$961,Disk!$A$2:$A$961,A3,Disk!$J$2:$J$961,"sda"),"не найдено") -> 1 | G3: =IF(COUNTIFS(Disk!$A$2:$A$961,A3,Disk!$J$2:$J$961,"sda2")=0,"не найдено",SUMIFS(Disk!$H$2:$H$961,Disk!$A$2:$A$961,A3,Disk!$J$2:$J$961,"sda2")) -> 1 | H3: =IF(COUNTIFS(Network!$A$2:$A$481,A3,Network!$B$2:$B$481,"enp0s3")=0,"не найдено",SUMIFS(Network!$K$2:$K$481,Network!$A$2:$A$481,A3,Network!$B$2:$B$481,"enp0s3")) -> 0.72 | I3: =IF(COUNTIFS(Network!$A$2:$A$481,A3,Network!$B$2:$B$481,"enp0s3")=0,"не найдено",SUMIFS(Network!$L$2:$L$481,Network!$A$2:$A$481,A3,Network!$B$2:$B$481,"enp0s3")) -> 11.84
A4: =Memory!A4 -> 0.20041667 | B4: =Memory!E4 -> 5.99 | C4: =Swap!D4 -> 0 | D4: =IFERROR(INDEX(Cpu!$I$2:$I$480,MATCH(A4,Cpu!$A$2:$A$480,0)),"не найдено") -> 0.33 | E4: =IFERROR(INDEX(Cpu!$J$2:$J$480,MATCH(A4,Cpu!$A$2:$A$480,0)),"не найдено") -> 0 | F4: =IFERROR(SUMIFS(Disk!$H$2:$H$961,Disk!$A$2:$A$961,A4,Disk!$J$2:$J$961,"sda"),"не найдено") -> 0.64 | G4: =IF(COUNTIFS(Disk!$A$2:$A$961,A4,Disk!$J$2:$J$961,"sda2")=0,"не найдено",SUMIFS(Disk!$H$2:$H$961,Disk!$A$2:$A$961,A4,Disk!$J$2:$J$961,"sda2")) -> 0.64 | H4: =IF(COUNTIFS(Network!$A$2:$A$481,A4,Network!$B$2:$B$481,"enp0s3")=0,"не найдено",SUMIFS(Network!$K$2:$K$481,Network!$A$2:$A$481,A4,Network!$B$2:$B$481,"enp0s3")) -> 0.48 | I4: =IF(COUNTIFS(Network!$A$2:$A$481,A4,Network!$B$2:$B$481,"enp0s3")=0,"не найдено",SUMIFS(Network!$L$2:$L$481,Network!$A$2:$A$481,A4,Network!$B$2:$B$481,"enp0s3")) -> 11.68
A5: =Memory!A5 -> 0.20053241 | B5: =Memory!E5 -> 5.99 | C5: =Swap!D5 -> 0 | D5: =IFERROR(INDEX(Cpu!$I$2:$I$480,MATCH(A5,Cpu!$A$2:$A$480,0)),"не найдено") -> 0.22 | E5: =IFERROR(INDEX(Cpu!$J$2:$J$480,MATCH(A5,Cpu!$A$2:$A$480,0)),"не найдено") -> 0 | F5: =IFERROR(SUMIFS(Disk!$H$2:$H$961,Disk!$A$2:$A$961,A5,Disk!$J$2:$J$961,"sda"),"не найдено") -> 1 | G5: =IF(COUNTIFS(Disk!$A$2:$A$961,A5,Disk!$J$2:$J$961,"sda2")=0,"не найдено",SUMIFS(Disk!$H$2:$H$961,Disk!$A$2:$A$961,A5,Disk!$J$2:$J$961,"sda2")) -> 1 | H5: =IF(COUNTIFS(Network!$A$2:$A$481,A5,Network!$B$2:$B$481,"enp0s3")=0,"не найдено",SUMIFS(Network!$K$2:$K$481,Network!$A$2:$A$481,A5,Network!$B$2:$B$481,"enp0s3")) -> 1.04 | I5: =IF(COUNTIFS(Network!$A$2:$A$481,A5,Network!$B$2:$B$481,"enp0s3")=0,"не найдено",SUMIFS(Network!$L$2:$L$481,Network!$A$2:$A$481,A5,Network!$B$2:$B$481,"enp0s3")) -> 11.76
A6: =Memory!A6 -> 0.20064815 | B6: =Memory!E6 -> 5.99 | C6: =Swap!D6 -> 0 | D6: =IFERROR(INDEX(Cpu!$I$2:$I$480,MATCH(A6,Cpu!$A$2:$A$480,0)),"не найдено") -> 0.33 | E6: =IFERROR(INDEX(Cpu!$J$2:$J$480,MATCH(A6,Cpu!$A$2:$A$480,0)),"не найдено") -> 0 | F6: =IFERROR(SUMIFS(Disk!$H$2:$H$961,Disk!$A$2:$A$961,A6,Disk!$J$2:$J$961,"sda"),"не найдено") -> 1 | G6: =IF(COUNTIFS(Disk!$A$2:$A$961,A6,Disk!$J$2:$J$961,"sda2")=0,"не найдено",SUMIFS(Disk!$H$2:$H$961,Disk!$A$2:$A$961,A6,Disk!$J$2:$J$961,"sda2")) -> 1 | H6: =IF(COUNTIFS(Network!$A$2:$A$481,A6,Network!$B$2:$B$481,"enp0s3")=0,"не найдено",SUMIFS(Network!$K$2:$K$481,Network!$A$2:$A$481,A6,Network!$B$2:$B$481,"enp0s3")) -> 0.72 | I6: =IF(COUNTIFS(Network!$A$2:$A$481,A6,Network!$B$2:$B$481,"enp0s3")=0,"не найдено",SUMIFS(Network!$L$2:$L$481,Network!$A$2:$A$481,A6,Network!$B$2:$B$481,"enp0s3")) -> 11.76
A7: =Memory!A7 -> 0.20076389 | B7: =Memory!E7 -> 5.99 | C7: =Swap!D7 -> 0 | D7: =IFERROR(INDEX(Cpu!$I$2:$I$480,MATCH(A7,Cpu!$A$2:$A$480,0)),"не найдено") -> 0.22 | E7: =IFERROR(INDEX(Cpu!$J$2:$J$480,MATCH(A7,Cpu!$A$2:$A$480,0)),"не найдено") -> 0 | F7: =IFERROR(SUMIFS(Disk!$H$2:$H$961,Disk!$A$2:$A$961,A7,Disk!$J$2:$J$961,"sda"),"не найдено") -> 0.67 | G7: =IF(COUNTIFS(Disk!$A$2:$A$961,A7,Disk!$J$2:$J$961,"sda2")=0,"не найдено",SUMIFS(Disk!$H$2:$H$961,Disk!$A$2:$A$961,A7,Disk!$J$2:$J$961,"sda2")) -> 0.67 | H7: =IF(COUNTIFS(Network!$A$2:$A$481,A7,Network!$B$2:$B$481,"enp0s3")=0,"не найдено",SUMIFS(Network!$K$2:$K$481,Network!$A$2:$A$481,A7,Network!$B$2:$B$481,"enp0s3")) -> 0.56 | I7: =IF(COUNTIFS(Network!$A$2:$A$481,A7,Network!$B$2:$B$481,"enp0s3")=0,"не найдено",SUMIFS(Network!$L$2:$L$481,Network!$A$2:$A$481,A7,Network!$B$2:$B$481,"enp0s3")) -> 11.76
A8: =Memory!A8 -> 0.20087963 | B8: =Memory!E8 -> 5.99 | C8: =Swap!D8 -> 0 | D8: =IFERROR(INDEX(Cpu!$I$2:$I$480,MATCH(A8,Cpu!$A$2:$A$480,0)),"не найдено") -> 0.33 | E8: =IFERROR(INDEX(Cpu!$J$2:$J$480,MATCH(A8,Cpu!$A$2:$A$480,0)),"не найдено") -> 0 | F8: =IFERROR(SUMIFS(Disk!$H$2:$H$961,Disk!$A$2:$A$961,A8,Disk!$J$2:$J$961,"sda"),"не найдено") -> 1 | G8: =IF(COUNTIFS(Disk!$A$2:$A$961,A8,Disk!$J$2:$J$961,"sda2")=0,"не найдено",SUMIFS(Disk!$H$2:$H$961,Disk!$A$2:$A$961,A8,Disk!$J$2:$J$961,"sda2")) -> 1 | H8: =IF(COUNTIFS(Network!$A$2:$A$481,A8,Network!$B$2:$B$481,"enp0s3")=0,"не найдено",SUMIFS(Network!$K$2:$K$481,Network!$A$2:$A$481,A8,Network!$B$2:$B$481,"enp0s3")) -> 1.04 | I8: =IF(COUNTIFS(Network!$A$2:$A$481,A8,Network!$B$2:$B$481,"enp0s3")=0,"не найдено",SUMIFS(Network!$L$2:$L$481,Network!$A$2:$A$481,A8,Network!$B$2:$B$481,"enp0s3")) -> 11.68
A9: =Memory!A9 -> 0.20099537 | B9: =Memory!E9 -> 5.99 | C9: =Swap!D9 -> 0 | D9: =IFERROR(INDEX(Cpu!$I$2:$I$480,MATCH(A9,Cpu!$A$2:$A$480,0)),"не найдено") -> 0.44 | E9: =IFERROR(INDEX(Cpu!$J$2:$J$480,MATCH(A9,Cpu!$A$2:$A$480,0)),"не найдено") -> 0 | F9: =IFERROR(SUMIFS(Disk!$H$2:$H$961,Disk!$A$2:$A$961,A9,Disk!$J$2:$J$961,"sda"),"не найдено") -> 1 | G9: =IF(COUNTIFS(Disk!$A$2:$A$961,A9,Disk!$J$2:$J$961,"sda2")=0,"не найдено",SUMIFS(Disk!$H$2:$H$961,Disk!$A$2:$A$961,A9,Disk!$J$2:$J$961,"sda2")) -> 1 | H9: =IF(COUNTIFS(Network!$A$2:$A$481,A9,Network!$B$2:$B$481,"enp0s3")=0,"не найдено",SUMIFS(Network!$K$2:$K$481,Network!$A$2:$A$481,A9,Network!$B$2:$B$481,"enp0s3")) -> 0.88 | I9: =IF(COUNTIFS(Network!$A$2:$A$481,A9,Network!$B$2:$B$481,"enp0s3")=0,"не найдено",SUMIFS(Network!$L$2:$L$481,Network!$A$2:$A$481,A9,Network!$B$2:$B$481,"enp0s3")) -> 11.76
A10: =Memory!A10 -> 0.20111111 | B10: =Memory!E10 -> 5.99 | C10: =Swap!D10 -> 0 | D10: =IFERROR(INDEX(Cpu!$I$2:$I$480,MATCH(A10,Cpu!$A$2:$A$480,0)),"не найдено") -> 0.33 | E10: =IFERROR(INDEX(Cpu!$J$2:$J$480,MATCH(A10,Cpu!$A$2:$A$480,0)),"не найдено") -> 0 | F10: =IFERROR(SUMIFS(Disk!$H$2:$H$961,Disk!$A$2:$A$961,A10,Disk!$J$2:$J$961,"sda"),"не найдено") -> 1.5 | G10: =IF(COUNTIFS(Disk!$A$2:$A$961,A10,Disk!$J$2:$J$961,"sda2")=0,"не найдено",SUMIFS(Disk!$H$2:$H$961,Disk!$A$2:$A$961,A10,Disk!$J$2:$J$961,"sda2")) -> 1.5 | H10: =IF(COUNTIFS(Network!$A$2:$A$481,A10,Network!$B$2:$B$481,"enp0s3")=0,"не найдено",SUMIFS(Network!$K$2:$K$481,Network!$A$2:$A$481,A10,Network!$B$2:$B$481,"enp0s3")) -> 0.64 | I10: =IF(COUNTIFS(Network!$A$2:$A$481,A10,Network!$B$2:$B$481,"enp0s3")=0,"не найдено",SUMIFS(Network!$L$2:$L$481,Network!$A$2:$A$481,A10,Network!$B$2:$B$481,"enp0s3")) -> 11.76
A11: =Memory!A11 -> 0.20122685 | B11: =Memory!E11 -> 5.98 | C11: =Swap!D11 -> 0 | D11: =IFERROR(INDEX(Cpu!$I$2:$I$480,MATCH(A11,Cpu!$A$2:$A$480,0)),"не найдено") -> 0.33 | E11: =IFERROR(INDEX(Cpu!$J$2:$J$480,MATCH(A11,Cpu!$A$2:$A$480,0)),"не найдено") -> 0 | F11: =IFERROR(SUMIFS(Disk!$H$2:$H$961,Disk!$A$2:$A$961,A11,Disk!$J$2:$J$961,"sda"),"не найдено") -> 1 | G11: =IF(COUNTIFS(Disk!$A$2:$A$961,A11,Disk!$J$2:$J$961,"sda2")=0,"не найдено",SUMIFS(Disk!$H$2:$H$961,Disk!$A$2:$A$961,A11,Disk!$J$2:$J$961,"sda2")) -> 1 | H11: =IF(COUNTIFS(Network!$A$2:$A$481,A11,Network!$B$2:$B$481,"enp0s3")=0,"не найдено",SUMIFS(Network!$K$2:$K$481,Network!$A$2:$A$481,A11,Network!$B$2:$B$481,"enp0s3")) -> 0.8 | I11: =IF(COUNTIFS(Network!$A$2:$A$481,A11,Network!$B$2:$B$481,"enp0s3")=0,"не найдено",SUMIFS(Network!$L$2:$L$481,Network!$A$2:$A$481,A11,Network!$B$2:$B$481,"enp0s3")) -> 11.76
A12: =Memory!A12 -> 0.20134259 | B12: =Memory!E12 -> 5.98 | C12: =Swap!D12 -> 0 | D12: =IFERROR(INDEX(Cpu!$I$2:$I$480,MATCH(A12,Cpu!$A$2:$A$480,0)),"не найдено") -> 0.22 | E12: =IFERROR(INDEX(Cpu!$J$2:$J$480,MATCH(A12,Cpu!$A$2:$A$480,0)),"не найдено") -> 0 | F12: =IFERROR(SUMIFS(Disk!$H$2:$H$961,Disk!$A$2:$A$961,A12,Disk!$J$2:$J$961,"sda"),"не найдено") -> 1.2 | G12: =IF(COUNTIFS(Disk!$A$2:$A$961,A12,Disk!$J$2:$J$961,"sda2")=0,"не найдено",SUMIFS(Disk!$H$2:$H$961,Disk!$A$2:$A$961,A12,Disk!$J$2:$J$961,"sda2")) -> 1.2 | H12: =IF(COUNTIFS(Network!$A$2:$A$481,A12,Network!$B$2:$B$481,"enp0s3")=0,"не найдено",SUMIFS(Network!$K$2:$K$481,Network!$A$2:$A$481,A12,Network!$B$2:$B$481,"enp0s3")) -> 0.56 | I12: =IF(COUNTIFS(Network!$A$2:$A$481,A12,Network!$B$2:$B$481,"enp0s3")=0,"не найдено",SUMIFS(Network!$L$2:$L$481,Network!$A$2:$A$481,A12,Network!$B$2:$B$481,"enp0s3")) -> 11.68
A13: =Memory!A13 -> 0.20145833 | B13: =Memory!E13 -> 5.99 | C13: =Swap!D13 -> 0 | D13: =IFERROR(INDEX(Cpu!$I$2:$I$480,MATCH(A13,Cpu!$A$2:$A$480,0)),"не найдено") -> 0.44 | E13: =IFERROR(INDEX(Cpu!$J$2:$J$480,MATCH(A13,Cpu!$A$2:$A$480,0)),"не найдено") -> 0 | F13: =IFERROR(SUMIFS(Disk!$H$2:$H$961,Disk!$A$2:$A$961,A13,Disk!$J$2:$J$961,"sda"),"не найдено") -> 0.8 | G13: =IF(COUNTIFS(Disk!$A$2:$A$961,A13,Disk!$J$2:$J$961,"sda2")=0,"не найдено",SUMIFS(Disk!$H$2:$H$961,Disk!$A$2:$A$961,A13,Disk!$J$2:$J$961,"sda2")) -> 0.8 | H13: =IF(COUNTIFS(Network!$A$2:$A$481,A13,Network!$B$2:$B$481,"enp0s3")=0,"не найдено",SUMIFS(Network!$K$2:$K$481,Network!$A$2:$A$481,A13,Network!$B$2:$B$481,"enp0s3")) -> 1.12 | I13: =IF(COUNTIFS(Network!$A$2:$A$481,A13,Network!$B$2:$B$481,"enp0s3")=0,"не найдено",SUMIFS(Network!$L$2:$L$481,Network!$A$2:$A$481,A13,Network!$B$2:$B$481,"enp0s3")) -> 11.76
... A241: =Memory!A241 -> 0.22784722 | B241: =Memory!E241 -> 7.45 | C241: =Swap!D241 -> 0 | D241: =IFERROR(INDEX(Cpu!$I$2:$I$480,MATCH(A241,Cpu!$A$2:$A$480,0)),"не найдено") -> 0.44 | E241: =IFERROR(INDEX(Cpu!$J$2:$J$480,MATCH(A241,Cpu!$A$2:$A$480,0)),"не найдено") -> 0 | F241: =IFERROR(SUMIFS(Disk!$H$2:$H$961,Disk!$A$2:$A$961,A241,Disk!$J$2:$J$961,"sda"),"не найдено") -> 1 | G241: =IF(COUNTIFS(Disk!$A$2:$A$961,A241,Disk!$J$2:$J$961,"sda2")=0,"не найдено",SUMIFS(Disk!$H$2:$H$961,Disk!$A$2:$A$961,A241,Disk!$J$2:$J$961,"sda2")) -> 1 | H241: =IF(COUNTIFS(Network!$A$2:$A$481,A241,Network!$B$2:$B$481,"enp0s3")=0,"не найдено",SUMIFS(Network!$K$2:$K$481,Network!$A$2:$A$481,A241,Network!$B$2:$B$481,"enp0s3")) -> 0.56 | I241: =IF(COUNTIFS(Network!$A$2:$A$481,A241,Network!$B$2:$B$481,"enp0s3")=0,"не найдено",SUMIFS(Network!$L$2:$L$481,Network!$A$2:$A$481,A241,Network!$B$2:$B$481,"enp0s3")) -> 11.76
